Traceback (most recent call last):
  File "/home/mudit/bot-battle/risk-engine/src/risk_engine/game_engine.py", line 51, in start
    self._run_game()
  File "/home/mudit/bot-battle/risk-engine/src/risk_engine/game_engine.py", line 149, in _run_game
    self._attack_phase(player, connection)
  File "/home/mudit/bot-battle/risk-engine/src/risk_engine/game_engine.py", line 225, in _attack_phase
    defend = self.connections[defending_player].query_defend(self.state, self.validator, self.censor, move_attack_id)
  File "/home/mudit/bot-battle/risk-engine/src/risk_engine/connection/player_connection.py", line 224, in query_defend
    query = QueryDefend(move_attack_id=move_attack_id, update=self._get_record_update_dict(state, censor))
  File "/home/mudit/bot-battle/risk-engine/src/risk_engine/connection/player_connection.py", line 203, in _get_record_update_dict
    result = dict([(i, censor.censor(x, self.player_id)) for i, x in list(enumerate(state.recording))[self._record_update_watermark:]])
KeyboardInterrupt

During handling of the above exception, another exception occurred:

Traceback (most recent call last):
  File "/usr/lib/python3.10/runpy.py", line 196, in _run_module_as_main
    return _run_code(code, main_globals, None,
  File "/usr/lib/python3.10/runpy.py", line 86, in _run_code
    exec(code, run_globals)
  File "/home/mudit/bot-battle/risk-engine/src/risk_engine/__main__.py", line 5, in <module>
    game.start()
  File "/home/mudit/bot-battle/risk-engine/src/risk_engine/game_engine.py", line 56, in start
    self._finish()
  File "/home/mudit/bot-battle/risk-engine/src/risk_engine/game_engine.py", line 105, in _finish
    print(f"[engine]: match complete, outcome was {{{result}}}", flush=True)
BrokenPipeError: [Errno 32] Broken pipe
Exception ignored in: <_io.TextIOWrapper name='<stdout>' mode='w' encoding='utf-8'>
BrokenPipeError: [Errno 32] Broken pipe
