Traceback (most recent call last):
  File "/home/mudit/bot-battle/risk-engine/src/risk_engine/game_engine.py", line 51, in start
    self._run_game()
  File "/home/mudit/bot-battle/risk-engine/src/risk_engine/game_engine.py", line 149, in _run_game
    self._attack_phase(player, connection)
  File "/home/mudit/bot-battle/risk-engine/src/risk_engine/game_engine.py", line 217, in _attack_phase
    attack = connection.query_attack(self.state, self.validator, self.censor)
  File "/home/mudit/bot-battle/risk-engine/src/risk_engine/connection/player_connection.py", line 230, in query_attack
    return self._query_move_union(query, MoveAttack, MoveAttackPass, validator)
  File "/home/mudit/bot-battle/risk-engine/src/risk_engine/connection/player_connection.py", line 81, in dfn
    result = fn(*args, **kwargs)
  File "/home/mudit/bot-battle/risk-engine/src/risk_engine/connection/player_connection.py", line 65, in dfn
    result = fn(*args, **kwargs)
  File "/home/mudit/bot-battle/risk-engine/src/risk_engine/connection/player_connection.py", line 109, in dfn2
    result = fn(*args, **kwargs)
  File "/home/mudit/bot-battle/risk-engine/src/risk_engine/connection/player_connection.py", line 202, in _query_move_union
    move = adapter.validate_json(self._receive())
  File "/home/mudit/bot-battle/risk-engine/src/risk_engine/connection/player_connection.py", line 157, in _receive
    buffer.extend(self._to_engine_pipe.read(1).encode())
KeyboardInterrupt

During handling of the above exception, another exception occurred:

Traceback (most recent call last):
  File "/usr/lib/python3.10/runpy.py", line 196, in _run_module_as_main
    return _run_code(code, main_globals, None,
  File "/usr/lib/python3.10/runpy.py", line 86, in _run_code
    exec(code, run_globals)
  File "/home/mudit/bot-battle/risk-engine/src/risk_engine/__main__.py", line 6, in <module>
    game.start()
  File "/home/mudit/bot-battle/risk-engine/src/risk_engine/game_engine.py", line 56, in start
    self._finish()
  File "/home/mudit/bot-battle/risk-engine/src/risk_engine/game_engine.py", line 105, in _finish
    print(f"[engine]: match complete, outcome was {{{result}}}", flush=True)
BrokenPipeError: [Errno 32] Broken pipe
Exception ignored in: <_io.TextIOWrapper name='<stdout>' mode='w' encoding='utf-8'>
BrokenPipeError: [Errno 32] Broken pipe
